<?xml version="1.0"?>
<robot name="custom_4wheel_robot" xmlns:xacro="http://www.ros.org/wiki/xacro">

  <xacro:include filename="properties.xacro" />

  <link name="base_footprint"/>

  <joint name="base_footprint_joint" type="fixed">
    <parent link="base_footprint"/>
    <child link="base_link"/>
    <origin xyz="0 0 0.15" rpy="0 0 0"/>
  </joint>

  <link name="base_link">
    <visual>
      <geometry>
        <box size="${base_length} ${base_width} ${base_height}"/>
      </geometry>
      <material name="chassis_color">
        <color rgba="0.1 0.5 0.8 1.0"/> </material>
    </visual>
    <collision>
      <geometry>
        <box size="${base_length} ${base_width} ${base_height}"/>
      </geometry>
    </collision>
    <inertial>
      <mass value="${base_mass}"/>
      <origin xyz="0 0 0" rpy="0 0 0"/>
      <inertia ixx="${(1/12) * base_mass * (base_width*base_width + base_height*base_height)}" ixy="0.0" ixz="0.0"
               iyy="${(1/12) * base_mass * (base_length*base_length + base_height*base_height)}" iyz="0.0"
               izz="${(1/12) * base_mass * (base_length*base_length + base_width*base_width)}"/>
    </inertial>
  </link>

  <xacro:macro name="wheel" params="prefix x_reflect y_reflect">
    
    <joint name="${prefix}_wheel_joint" type="continuous">
      <parent link="base_link"/>
      <child link="${prefix}_wheel_link"/>
      <origin xyz="${x_reflect * wheel_x_offset} ${y_reflect * wheel_y_offset} ${wheel_z_offset}" rpy="0 0 0"/>
      <axis xyz="0 1 0"/> </joint>

    <link name="${prefix}_wheel_link">
      <visual>
        <origin xyz="0 0 0" rpy="${pi/2} 0 0"/>
        <geometry>
          <cylinder radius="${wheel_radius}" length="${wheel_width}"/>
        </geometry>
        <material name="wheel_color">
          <color rgba="0.1 0.1 0.1 1.0"/> </material>
      </visual>
      <collision>
        <origin xyz="0 0 0" rpy="${pi/2} 0 0"/>
        <geometry>
          <cylinder radius="${wheel_radius}" length="${wheel_width}"/>
        </geometry>
      </collision>
      <inertial>
        <mass value="${wheel_mass}"/>
        <origin xyz="0 0 0" rpy="${pi/2} 0 0"/>
        <inertia ixx="${(1/12) * wheel_mass * (3*wheel_radius*wheel_radius + wheel_width*wheel_width)}" ixy="0.0" ixz="0.0"
                 iyy="${(1/12) * wheel_mass * (3*wheel_radius*wheel_radius + wheel_width*wheel_width)}" iyz="0.0"
                 izz="${(1/2) * wheel_mass * (wheel_radius*wheel_radius)}"/>
      </inertial>
    </link>
  </xacro:macro>

  <xacro:wheel prefix="front_left"  x_reflect="1"  y_reflect="1" />
  <xacro:wheel prefix="front_right" x_reflect="1"  y_reflect="-1" />
  <xacro:wheel prefix="rear_left"   x_reflect="-1" y_reflect="1" />
  <xacro:wheel prefix="rear_right"  x_reflect="-1" y_reflect="-1" />

</robot>